TICK
Traceback (most recent call last):
  File "/usr/lib/python3.4/asyncio/base_events.py", line 823, in create_server
    sock.bind(sa)
OSError: [Errno 98] Address already in use

During handling of the above exception, another exception occurred:

Traceback (most recent call last):
  File "./serverprocmon.py", line 366, in <module>
    loop.run_until_complete(start_ws_server)
  File "/usr/lib/python3.4/asyncio/base_events.py", line 316, in run_until_complete
    return future.result()
  File "/usr/lib/python3.4/asyncio/futures.py", line 275, in result
    raise self._exception
  File "/usr/lib/python3.4/asyncio/tasks.py", line 236, in _step
    result = coro.send(value)
  File "/usr/local/lib/python3.4/dist-packages/websockets/server.py", line 226, in serve
    return (yield from loop.create_server(factory, host, port, **kwds))
  File "/usr/lib/python3.4/asyncio/base_events.py", line 827, in create_server
    % (sa, err.strerror.lower()))
OSError: [Errno 98] error while attempting to bind on address ('0.0.0.0', 8765): address already in use
